Traceback (most recent call last):
  File "C:\python_venv\psqlpy_venv\Lib\site-packages\nbclient\client.py", line 778, in _async_poll_for_reply
    msg = await ensure_async(self.kc.shell_channel.get_msg(timeout=new_timeout))
          ^^^^^^^^^^^^^^^^^^^^^^^^^^^^^^^^^^^^^^^^^^^^^^^^^^^^^^^^^^^^^^^^^^^^^^
  File "C:\python_venv\psqlpy_venv\Lib\site-packages\jupyter_core\utils\__init__.py", line 189, in ensure_async
    result = await obj
             ^^^^^^^^^
  File "C:\python_venv\psqlpy_venv\Lib\site-packages\jupyter_client\channels.py", line 315, in get_msg
    raise Empty
_queue.Empty

During handling of the above exception, another exception occurred:

Traceback (most recent call last):
  File "C:\python_venv\psqlpy_venv\Lib\site-packages\jupyter_cache\executors\utils.py", line 58, in single_nb_execution
    executenb(
  File "C:\python_venv\psqlpy_venv\Lib\site-packages\nbclient\client.py", line 1305, in execute
    return NotebookClient(nb=nb, resources=resources, km=km, **kwargs).execute()
           ^^^^^^^^^^^^^^^^^^^^^^^^^^^^^^^^^^^^^^^^^^^^^^^^^^^^^^^^^^^^^^^^^^^^^
  File "C:\python_venv\psqlpy_venv\Lib\site-packages\jupyter_core\utils\__init__.py", line 173, in wrapped
    return loop.run_until_complete(inner)
           ^^^^^^^^^^^^^^^^^^^^^^^^^^^^^^
  File "C:\Program Files\WindowsApps\PythonSoftwareFoundation.Python.3.11_3.11.1776.0_x64__qbz5n2kfra8p0\Lib\asyncio\base_events.py", line 653, in run_until_complete
    return future.result()
           ^^^^^^^^^^^^^^^
  File "C:\python_venv\psqlpy_venv\Lib\site-packages\nbclient\client.py", line 705, in async_execute
    await self.async_execute_cell(
  File "C:\python_venv\psqlpy_venv\Lib\site-packages\nbclient\client.py", line 1001, in async_execute_cell
    exec_reply = await self.task_poll_for_reply
                 ^^^^^^^^^^^^^^^^^^^^^^^^^^^^^^
  File "C:\python_venv\psqlpy_venv\Lib\site-packages\nbclient\client.py", line 802, in _async_poll_for_reply
    error_on_timeout_execute_reply = await self._async_handle_timeout(timeout, cell)
                                     ^^^^^^^^^^^^^^^^^^^^^^^^^^^^^^^^^^^^^^^^^^^^^^^
  File "C:\python_venv\psqlpy_venv\Lib\site-packages\nbclient\client.py", line 852, in _async_handle_timeout
    raise CellTimeoutError.error_from_timeout_and_cell(
nbclient.exceptions.CellTimeoutError: A cell timed out while it was being executed, after 30 seconds.
The message was: Cell execution timed out.
Here is a preview of the cell contents:
-------------------
["fig = sp.make_subplots(rows=6, cols=1, subplot_titles=('brnowl', 'comsan', 'houspa', 'mallar3', 'norcar', 'skylar'), vertical_spacing=0.1)", '', "fig.add_trace(go.Scatter(x=np.arange(0, len(audio_brnowl))/sr_brnowl, y=audio_brnowl, mode='lines', name='Onda de Audio'), row=1, col=1)", "fig.add_trace(go.Scatter(x=np.arange(0, len(audio_comsan))/sr_comsan, y=audio_comsan, mode='lines', name='Onda de Audio'), row=2, col=1)", "fig.add_trace(go.Scatter(x=np.arange(0, len(audio_houspa))/sr_houspa, y=audio_houspa, mode='lines', name='Onda de Audio'), row=3, col=1)"]
...
["fig.update_layout(title='Ondas de Audio Interactivas',", "                  xaxis_title='Tiempo (s)',", "                  yaxis_title='Amplitud', height=800)", '', 'fig.show()']
-------------------

